[0m18:31:01.301740 [debug] [MainThread]: Sending event: {'category': 'dbt', 'action': 'invocation', 'label': 'start', 'context': [<snowplow_tracker.self_describing_json.SelfDescribingJson object at 0x0000024F1AD88190>, <snowplow_tracker.self_describing_json.SelfDescribingJson object at 0x0000024F1EC888D0>, <snowplow_tracker.self_describing_json.SelfDescribingJson object at 0x0000024F1EEC1450>]}


============================== 18:31:01.305739 | 41903a50-ce63-4050-aeb1-d85d47a0d500 ==============================
[0m18:31:01.305739 [info ] [MainThread]: Running with dbt=1.9.3
[0m18:31:01.306739 [debug] [MainThread]: running dbt with arguments {'printer_width': '80', 'indirect_selection': 'eager', 'write_json': 'True', 'log_cache_events': 'False', 'partial_parse': 'True', 'cache_selected_only': 'False', 'warn_error': 'None', 'debug': 'False', 'version_check': 'True', 'log_path': 'logs', 'profiles_dir': 'C:\\Users\\acesk\\.dbt', 'fail_fast': 'False', 'use_colors': 'True', 'use_experimental_parser': 'False', 'empty': 'None', 'quiet': 'False', 'no_print': 'None', 'log_format': 'default', 'static_parser': 'True', 'introspect': 'True', 'warn_error_options': 'WarnErrorOptions(include=[], exclude=[])', 'target_path': 'None', 'invocation_command': 'dbt init analytics', 'send_anonymous_usage_stats': 'True'}
[0m18:31:01.319304 [debug] [MainThread]: Starter project path: C:\Users\acesk\data-engineering-project\venv\Lib\site-packages\dbt\include\starter_project
[0m18:31:01.342578 [info ] [MainThread]: 
Your new dbt project "analytics" was created!

For more information on how to configure the profiles.yml file,
please consult the dbt documentation here:

  https://docs.getdbt.com/docs/configure-your-profile

One more thing:

Need help? Don't hesitate to reach out to us via GitHub issues or on Slack:

  https://community.getdbt.com/

Happy modeling!

[0m18:31:01.343578 [info ] [MainThread]: Setting up your profile.
[0m18:31:23.913046 [error] [MainThread]: Encountered an error:
list index out of range
[0m18:31:23.916059 [error] [MainThread]: Traceback (most recent call last):
  File "C:\Users\acesk\data-engineering-project\venv\Lib\site-packages\dbt\cli\requires.py", line 153, in wrapper
    result, success = func(*args, **kwargs)
                      ^^^^^^^^^^^^^^^^^^^^^
  File "C:\Users\acesk\data-engineering-project\venv\Lib\site-packages\dbt\cli\requires.py", line 103, in wrapper
    return func(*args, **kwargs)
           ^^^^^^^^^^^^^^^^^^^^^
  File "C:\Users\acesk\data-engineering-project\venv\Lib\site-packages\dbt\cli\main.py", line 477, in init
    results = task.run()
              ^^^^^^^^^^
  File "C:\Users\acesk\data-engineering-project\venv\Lib\site-packages\dbt\task\init.py", line 346, in run
    self.setup_profile(profile_name)
  File "C:\Users\acesk\data-engineering-project\venv\Lib\site-packages\dbt\task\init.py", line 261, in setup_profile
    adapter = self.ask_for_adapter_choice()
              ^^^^^^^^^^^^^^^^^^^^^^^^^^^^^
  File "C:\Users\acesk\data-engineering-project\venv\Lib\site-packages\dbt\task\init.py", line 243, in ask_for_adapter_choice
    return available_adapters[numeric_choice - 1]
           ~~~~~~~~~~~~~~~~~~^^^^^^^^^^^^^^^^^^^^
IndexError: list index out of range

[0m18:31:23.918049 [debug] [MainThread]: Command `dbt init` failed at 18:31:23.918049 after 22.69 seconds
[0m18:31:23.918049 [debug] [MainThread]: Sending event: {'category': 'dbt', 'action': 'invocation', 'label': 'end', 'context': [<snowplow_tracker.self_describing_json.SelfDescribingJson object at 0x0000024F1EE76710>, <snowplow_tracker.self_describing_json.SelfDescribingJson object at 0x0000024F1EECFFD0>, <snowplow_tracker.self_describing_json.SelfDescribingJson object at 0x0000024F1EECD590>]}
[0m18:31:23.919050 [debug] [MainThread]: Flushing usage events
[0m18:31:25.229255 [debug] [MainThread]: An error was encountered while trying to flush usage events
[0m18:37:01.561499 [debug] [MainThread]: Sending event: {'category': 'dbt', 'action': 'invocation', 'label': 'start', 'context': [<snowplow_tracker.self_describing_json.SelfDescribingJson object at 0x000002855198F090>, <snowplow_tracker.self_describing_json.SelfDescribingJson object at 0x0000028550F62050>, <snowplow_tracker.self_describing_json.SelfDescribingJson object at 0x00000285547DF010>]}


============================== 18:37:01.565522 | c847d699-0780-478b-b20f-f701cad335af ==============================
[0m18:37:01.565522 [info ] [MainThread]: Running with dbt=1.9.3
[0m18:37:01.567030 [debug] [MainThread]: running dbt with arguments {'printer_width': '80', 'indirect_selection': 'eager', 'log_cache_events': 'False', 'write_json': 'True', 'partial_parse': 'True', 'cache_selected_only': 'False', 'profiles_dir': 'C:\\Users\\acesk\\.dbt', 'debug': 'False', 'version_check': 'True', 'log_path': 'logs', 'fail_fast': 'False', 'warn_error': 'None', 'use_colors': 'True', 'use_experimental_parser': 'False', 'no_print': 'None', 'quiet': 'False', 'empty': 'None', 'warn_error_options': 'WarnErrorOptions(include=[], exclude=[])', 'static_parser': 'True', 'invocation_command': 'dbt init analytics', 'introspect': 'True', 'target_path': 'None', 'log_format': 'default', 'send_anonymous_usage_stats': 'True'}
[0m18:37:01.579102 [debug] [MainThread]: Starter project path: C:\Users\acesk\data-engineering-project\venv\Lib\site-packages\dbt\include\starter_project
[0m18:37:01.589888 [info ] [MainThread]: 
Your new dbt project "analytics" was created!

For more information on how to configure the profiles.yml file,
please consult the dbt documentation here:

  https://docs.getdbt.com/docs/configure-your-profile

One more thing:

Need help? Don't hesitate to reach out to us via GitHub issues or on Slack:

  https://community.getdbt.com/

Happy modeling!

[0m18:37:01.590898 [info ] [MainThread]: Setting up your profile.
[0m18:37:31.178268 [error] [MainThread]: Encountered an error:

[0m18:37:31.213295 [error] [MainThread]: Traceback (most recent call last):
  File "C:\Users\acesk\data-engineering-project\venv\Lib\site-packages\dbt\cli\requires.py", line 153, in wrapper
    result, success = func(*args, **kwargs)
                      ^^^^^^^^^^^^^^^^^^^^^
  File "C:\Users\acesk\data-engineering-project\venv\Lib\site-packages\dbt\cli\requires.py", line 103, in wrapper
    return func(*args, **kwargs)
           ^^^^^^^^^^^^^^^^^^^^^
  File "C:\Users\acesk\data-engineering-project\venv\Lib\site-packages\dbt\cli\main.py", line 477, in init
    results = task.run()
              ^^^^^^^^^^
  File "C:\Users\acesk\data-engineering-project\venv\Lib\site-packages\dbt\task\init.py", line 346, in run
    self.setup_profile(profile_name)
  File "C:\Users\acesk\data-engineering-project\venv\Lib\site-packages\dbt\task\init.py", line 261, in setup_profile
    adapter = self.ask_for_adapter_choice()
              ^^^^^^^^^^^^^^^^^^^^^^^^^^^^^
  File "C:\Users\acesk\data-engineering-project\venv\Lib\site-packages\dbt\task\init.py", line 242, in ask_for_adapter_choice
    numeric_choice = click.prompt(prompt_msg, type=click.INT)
                     ^^^^^^^^^^^^^^^^^^^^^^^^^^^^^^^^^^^^^^^^
  File "C:\Users\acesk\data-engineering-project\venv\Lib\site-packages\click\termui.py", line 164, in prompt
    value = prompt_func(prompt)
            ^^^^^^^^^^^^^^^^^^^
  File "C:\Users\acesk\data-engineering-project\venv\Lib\site-packages\click\termui.py", line 147, in prompt_func
    raise Abort() from None
click.exceptions.Abort

[0m18:37:31.215373 [debug] [MainThread]: Command `dbt init` failed at 18:37:31.215373 after 29.73 seconds
[0m18:37:31.215373 [debug] [MainThread]: Sending event: {'category': 'dbt', 'action': 'invocation', 'label': 'end', 'context': [<snowplow_tracker.self_describing_json.SelfDescribingJson object at 0x00000285568CDAD0>, <snowplow_tracker.self_describing_json.SelfDescribingJson object at 0x0000028556876690>, <snowplow_tracker.self_describing_json.SelfDescribingJson object at 0x00000285568C3290>]}
[0m18:37:31.215373 [debug] [MainThread]: Flushing usage events
[0m18:37:32.463242 [debug] [MainThread]: An error was encountered while trying to flush usage events
